[2021-11-12 17:27:28,340] |  ERROR | {/home/julien/PycharmProjects/website/venv/lib/python3.9/site-packages/flask/app.py:1454} | Exception on /edit_profile [POST]
Traceback (most recent call last):
  File "/home/julien/PycharmProjects/website/venv/lib/python3.9/site-packages/sqlalchemy/engine/base.py", line 1771, in _execute_context
    self.dialect.do_execute(
  File "/home/julien/PycharmProjects/website/venv/lib/python3.9/site-packages/sqlalchemy/engine/default.py", line 717, in do_execute
    cursor.execute(statement, parameters)
sqlite3.IntegrityError: UNIQUE constraint failed: user.username

The above exception was the direct cause of the following exception:

Traceback (most recent call last):
  File "/home/julien/PycharmProjects/website/venv/lib/python3.9/site-packages/flask/app.py", line 2070, in wsgi_app
    response = self.full_dispatch_request()
  File "/home/julien/PycharmProjects/website/venv/lib/python3.9/site-packages/flask/app.py", line 1515, in full_dispatch_request
    rv = self.handle_user_exception(e)
  File "/home/julien/PycharmProjects/website/venv/lib/python3.9/site-packages/flask/app.py", line 1513, in full_dispatch_request
    rv = self.dispatch_request()
  File "/home/julien/PycharmProjects/website/venv/lib/python3.9/site-packages/flask/app.py", line 1499, in dispatch_request
    return self.ensure_sync(self.view_functions[rule.endpoint])(**req.view_args)
  File "/home/julien/PycharmProjects/website/venv/lib/python3.9/site-packages/flask_login/utils.py", line 272, in decorated_view
    return func(*args, **kwargs)
  File "/home/julien/PycharmProjects/website/app/blog/routes.py", line 91, in edit_profile
    db.session.commit()
  File "<string>", line 2, in commit
  File "/home/julien/PycharmProjects/website/venv/lib/python3.9/site-packages/sqlalchemy/orm/session.py", line 1428, in commit
    self._transaction.commit(_to_root=self.future)
  File "/home/julien/PycharmProjects/website/venv/lib/python3.9/site-packages/sqlalchemy/orm/session.py", line 829, in commit
    self._prepare_impl()
  File "/home/julien/PycharmProjects/website/venv/lib/python3.9/site-packages/sqlalchemy/orm/session.py", line 808, in _prepare_impl
    self.session.flush()
  File "/home/julien/PycharmProjects/website/venv/lib/python3.9/site-packages/sqlalchemy/orm/session.py", line 3298, in flush
    self._flush(objects)
  File "/home/julien/PycharmProjects/website/venv/lib/python3.9/site-packages/sqlalchemy/orm/session.py", line 3438, in _flush
    transaction.rollback(_capture_exception=True)
  File "/home/julien/PycharmProjects/website/venv/lib/python3.9/site-packages/sqlalchemy/util/langhelpers.py", line 70, in __exit__
    compat.raise_(
  File "/home/julien/PycharmProjects/website/venv/lib/python3.9/site-packages/sqlalchemy/util/compat.py", line 207, in raise_
    raise exception
  File "/home/julien/PycharmProjects/website/venv/lib/python3.9/site-packages/sqlalchemy/orm/session.py", line 3398, in _flush
    flush_context.execute()
  File "/home/julien/PycharmProjects/website/venv/lib/python3.9/site-packages/sqlalchemy/orm/unitofwork.py", line 456, in execute
    rec.execute(self)
  File "/home/julien/PycharmProjects/website/venv/lib/python3.9/site-packages/sqlalchemy/orm/unitofwork.py", line 630, in execute
    util.preloaded.orm_persistence.save_obj(
  File "/home/julien/PycharmProjects/website/venv/lib/python3.9/site-packages/sqlalchemy/orm/persistence.py", line 234, in save_obj
    _emit_update_statements(
  File "/home/julien/PycharmProjects/website/venv/lib/python3.9/site-packages/sqlalchemy/orm/persistence.py", line 998, in _emit_update_statements
    c = connection._execute_20(
  File "/home/julien/PycharmProjects/website/venv/lib/python3.9/site-packages/sqlalchemy/engine/base.py", line 1583, in _execute_20
    return meth(self, args_10style, kwargs_10style, execution_options)
  File "/home/julien/PycharmProjects/website/venv/lib/python3.9/site-packages/sqlalchemy/sql/elements.py", line 323, in _execute_on_connection
    return connection._execute_clauseelement(
  File "/home/julien/PycharmProjects/website/venv/lib/python3.9/site-packages/sqlalchemy/engine/base.py", line 1452, in _execute_clauseelement
    ret = self._execute_context(
  File "/home/julien/PycharmProjects/website/venv/lib/python3.9/site-packages/sqlalchemy/engine/base.py", line 1814, in _execute_context
    self._handle_dbapi_exception(
  File "/home/julien/PycharmProjects/website/venv/lib/python3.9/site-packages/sqlalchemy/engine/base.py", line 1995, in _handle_dbapi_exception
    util.raise_(
  File "/home/julien/PycharmProjects/website/venv/lib/python3.9/site-packages/sqlalchemy/util/compat.py", line 207, in raise_
    raise exception
  File "/home/julien/PycharmProjects/website/venv/lib/python3.9/site-packages/sqlalchemy/engine/base.py", line 1771, in _execute_context
    self.dialect.do_execute(
  File "/home/julien/PycharmProjects/website/venv/lib/python3.9/site-packages/sqlalchemy/engine/default.py", line 717, in do_execute
    cursor.execute(statement, parameters)
sqlalchemy.exc.IntegrityError: (sqlite3.IntegrityError) UNIQUE constraint failed: user.username
[SQL: UPDATE user SET username=?, about_me=? WHERE user.id = ?]
[parameters: ('susan', 'test', 2)]
(Background on this error at: https://sqlalche.me/e/14/gkpj)
[2021-11-12 17:29:45,351] |  ERROR | {/home/julien/PycharmProjects/website/venv/lib/python3.9/site-packages/flask/app.py:1454} | Exception on /edit_profile [POST]
Traceback (most recent call last):
  File "/home/julien/PycharmProjects/website/venv/lib/python3.9/site-packages/sqlalchemy/engine/base.py", line 1771, in _execute_context
    self.dialect.do_execute(
  File "/home/julien/PycharmProjects/website/venv/lib/python3.9/site-packages/sqlalchemy/engine/default.py", line 717, in do_execute
    cursor.execute(statement, parameters)
sqlite3.IntegrityError: UNIQUE constraint failed: user.username

The above exception was the direct cause of the following exception:

Traceback (most recent call last):
  File "/home/julien/PycharmProjects/website/venv/lib/python3.9/site-packages/flask/app.py", line 2070, in wsgi_app
    response = self.full_dispatch_request()
  File "/home/julien/PycharmProjects/website/venv/lib/python3.9/site-packages/flask/app.py", line 1515, in full_dispatch_request
    rv = self.handle_user_exception(e)
  File "/home/julien/PycharmProjects/website/venv/lib/python3.9/site-packages/flask/app.py", line 1513, in full_dispatch_request
    rv = self.dispatch_request()
  File "/home/julien/PycharmProjects/website/venv/lib/python3.9/site-packages/flask/app.py", line 1499, in dispatch_request
    return self.ensure_sync(self.view_functions[rule.endpoint])(**req.view_args)
  File "/home/julien/PycharmProjects/website/venv/lib/python3.9/site-packages/flask_login/utils.py", line 272, in decorated_view
    return func(*args, **kwargs)
  File "/home/julien/PycharmProjects/website/app/blog/routes.py", line 91, in edit_profile
    db.session.commit()
  File "<string>", line 2, in commit
  File "/home/julien/PycharmProjects/website/venv/lib/python3.9/site-packages/sqlalchemy/orm/session.py", line 1428, in commit
    self._transaction.commit(_to_root=self.future)
  File "/home/julien/PycharmProjects/website/venv/lib/python3.9/site-packages/sqlalchemy/orm/session.py", line 829, in commit
    self._prepare_impl()
  File "/home/julien/PycharmProjects/website/venv/lib/python3.9/site-packages/sqlalchemy/orm/session.py", line 808, in _prepare_impl
    self.session.flush()
  File "/home/julien/PycharmProjects/website/venv/lib/python3.9/site-packages/sqlalchemy/orm/session.py", line 3298, in flush
    self._flush(objects)
  File "/home/julien/PycharmProjects/website/venv/lib/python3.9/site-packages/sqlalchemy/orm/session.py", line 3438, in _flush
    transaction.rollback(_capture_exception=True)
  File "/home/julien/PycharmProjects/website/venv/lib/python3.9/site-packages/sqlalchemy/util/langhelpers.py", line 70, in __exit__
    compat.raise_(
  File "/home/julien/PycharmProjects/website/venv/lib/python3.9/site-packages/sqlalchemy/util/compat.py", line 207, in raise_
    raise exception
  File "/home/julien/PycharmProjects/website/venv/lib/python3.9/site-packages/sqlalchemy/orm/session.py", line 3398, in _flush
    flush_context.execute()
  File "/home/julien/PycharmProjects/website/venv/lib/python3.9/site-packages/sqlalchemy/orm/unitofwork.py", line 456, in execute
    rec.execute(self)
  File "/home/julien/PycharmProjects/website/venv/lib/python3.9/site-packages/sqlalchemy/orm/unitofwork.py", line 630, in execute
    util.preloaded.orm_persistence.save_obj(
  File "/home/julien/PycharmProjects/website/venv/lib/python3.9/site-packages/sqlalchemy/orm/persistence.py", line 234, in save_obj
    _emit_update_statements(
  File "/home/julien/PycharmProjects/website/venv/lib/python3.9/site-packages/sqlalchemy/orm/persistence.py", line 998, in _emit_update_statements
    c = connection._execute_20(
  File "/home/julien/PycharmProjects/website/venv/lib/python3.9/site-packages/sqlalchemy/engine/base.py", line 1583, in _execute_20
    return meth(self, args_10style, kwargs_10style, execution_options)
  File "/home/julien/PycharmProjects/website/venv/lib/python3.9/site-packages/sqlalchemy/sql/elements.py", line 323, in _execute_on_connection
    return connection._execute_clauseelement(
  File "/home/julien/PycharmProjects/website/venv/lib/python3.9/site-packages/sqlalchemy/engine/base.py", line 1452, in _execute_clauseelement
    ret = self._execute_context(
  File "/home/julien/PycharmProjects/website/venv/lib/python3.9/site-packages/sqlalchemy/engine/base.py", line 1814, in _execute_context
    self._handle_dbapi_exception(
  File "/home/julien/PycharmProjects/website/venv/lib/python3.9/site-packages/sqlalchemy/engine/base.py", line 1995, in _handle_dbapi_exception
    util.raise_(
  File "/home/julien/PycharmProjects/website/venv/lib/python3.9/site-packages/sqlalchemy/util/compat.py", line 207, in raise_
    raise exception
  File "/home/julien/PycharmProjects/website/venv/lib/python3.9/site-packages/sqlalchemy/engine/base.py", line 1771, in _execute_context
    self.dialect.do_execute(
  File "/home/julien/PycharmProjects/website/venv/lib/python3.9/site-packages/sqlalchemy/engine/default.py", line 717, in do_execute
    cursor.execute(statement, parameters)
sqlalchemy.exc.IntegrityError: (sqlite3.IntegrityError) UNIQUE constraint failed: user.username
[SQL: UPDATE user SET username=?, about_me=? WHERE user.id = ?]
[parameters: ('susan', 'test', 2)]
(Background on this error at: https://sqlalche.me/e/14/gkpj)
[2021-11-12 17:38:52,629] |  ERROR | {/home/julien/PycharmProjects/website/venv/lib/python3.9/site-packages/flask/app.py:1454} | Exception on /edit_profile [POST]
Traceback (most recent call last):
  File "/home/julien/PycharmProjects/website/venv/lib/python3.9/site-packages/sqlalchemy/engine/base.py", line 1771, in _execute_context
    self.dialect.do_execute(
  File "/home/julien/PycharmProjects/website/venv/lib/python3.9/site-packages/sqlalchemy/engine/default.py", line 717, in do_execute
    cursor.execute(statement, parameters)
sqlite3.IntegrityError: UNIQUE constraint failed: user.username

The above exception was the direct cause of the following exception:

Traceback (most recent call last):
  File "/home/julien/PycharmProjects/website/venv/lib/python3.9/site-packages/flask/app.py", line 2070, in wsgi_app
    response = self.full_dispatch_request()
  File "/home/julien/PycharmProjects/website/venv/lib/python3.9/site-packages/flask/app.py", line 1515, in full_dispatch_request
    rv = self.handle_user_exception(e)
  File "/home/julien/PycharmProjects/website/venv/lib/python3.9/site-packages/flask/app.py", line 1513, in full_dispatch_request
    rv = self.dispatch_request()
  File "/home/julien/PycharmProjects/website/venv/lib/python3.9/site-packages/flask/app.py", line 1499, in dispatch_request
    return self.ensure_sync(self.view_functions[rule.endpoint])(**req.view_args)
  File "/home/julien/PycharmProjects/website/venv/lib/python3.9/site-packages/flask_login/utils.py", line 272, in decorated_view
    return func(*args, **kwargs)
  File "/home/julien/PycharmProjects/website/app/blog/routes.py", line 91, in edit_profile
    db.session.commit()
  File "<string>", line 2, in commit
  File "/home/julien/PycharmProjects/website/venv/lib/python3.9/site-packages/sqlalchemy/orm/session.py", line 1428, in commit
    self._transaction.commit(_to_root=self.future)
  File "/home/julien/PycharmProjects/website/venv/lib/python3.9/site-packages/sqlalchemy/orm/session.py", line 829, in commit
    self._prepare_impl()
  File "/home/julien/PycharmProjects/website/venv/lib/python3.9/site-packages/sqlalchemy/orm/session.py", line 808, in _prepare_impl
    self.session.flush()
  File "/home/julien/PycharmProjects/website/venv/lib/python3.9/site-packages/sqlalchemy/orm/session.py", line 3298, in flush
    self._flush(objects)
  File "/home/julien/PycharmProjects/website/venv/lib/python3.9/site-packages/sqlalchemy/orm/session.py", line 3438, in _flush
    transaction.rollback(_capture_exception=True)
  File "/home/julien/PycharmProjects/website/venv/lib/python3.9/site-packages/sqlalchemy/util/langhelpers.py", line 70, in __exit__
    compat.raise_(
  File "/home/julien/PycharmProjects/website/venv/lib/python3.9/site-packages/sqlalchemy/util/compat.py", line 207, in raise_
    raise exception
  File "/home/julien/PycharmProjects/website/venv/lib/python3.9/site-packages/sqlalchemy/orm/session.py", line 3398, in _flush
    flush_context.execute()
  File "/home/julien/PycharmProjects/website/venv/lib/python3.9/site-packages/sqlalchemy/orm/unitofwork.py", line 456, in execute
    rec.execute(self)
  File "/home/julien/PycharmProjects/website/venv/lib/python3.9/site-packages/sqlalchemy/orm/unitofwork.py", line 630, in execute
    util.preloaded.orm_persistence.save_obj(
  File "/home/julien/PycharmProjects/website/venv/lib/python3.9/site-packages/sqlalchemy/orm/persistence.py", line 234, in save_obj
    _emit_update_statements(
  File "/home/julien/PycharmProjects/website/venv/lib/python3.9/site-packages/sqlalchemy/orm/persistence.py", line 998, in _emit_update_statements
    c = connection._execute_20(
  File "/home/julien/PycharmProjects/website/venv/lib/python3.9/site-packages/sqlalchemy/engine/base.py", line 1583, in _execute_20
    return meth(self, args_10style, kwargs_10style, execution_options)
  File "/home/julien/PycharmProjects/website/venv/lib/python3.9/site-packages/sqlalchemy/sql/elements.py", line 323, in _execute_on_connection
    return connection._execute_clauseelement(
  File "/home/julien/PycharmProjects/website/venv/lib/python3.9/site-packages/sqlalchemy/engine/base.py", line 1452, in _execute_clauseelement
    ret = self._execute_context(
  File "/home/julien/PycharmProjects/website/venv/lib/python3.9/site-packages/sqlalchemy/engine/base.py", line 1814, in _execute_context
    self._handle_dbapi_exception(
  File "/home/julien/PycharmProjects/website/venv/lib/python3.9/site-packages/sqlalchemy/engine/base.py", line 1995, in _handle_dbapi_exception
    util.raise_(
  File "/home/julien/PycharmProjects/website/venv/lib/python3.9/site-packages/sqlalchemy/util/compat.py", line 207, in raise_
    raise exception
  File "/home/julien/PycharmProjects/website/venv/lib/python3.9/site-packages/sqlalchemy/engine/base.py", line 1771, in _execute_context
    self.dialect.do_execute(
  File "/home/julien/PycharmProjects/website/venv/lib/python3.9/site-packages/sqlalchemy/engine/default.py", line 717, in do_execute
    cursor.execute(statement, parameters)
sqlalchemy.exc.IntegrityError: (sqlite3.IntegrityError) UNIQUE constraint failed: user.username
[SQL: UPDATE user SET username=?, about_me=? WHERE user.id = ?]
[parameters: ('julien', 'test', 1)]
(Background on this error at: https://sqlalche.me/e/14/gkpj)
[2021-11-12 18:06:08,957] |  ERROR | {/home/julien/PycharmProjects/website/venv/lib/python3.9/site-packages/flask/app.py:1454} | Exception on /edit_profile [POST]
Traceback (most recent call last):
  File "/home/julien/PycharmProjects/website/venv/lib/python3.9/site-packages/sqlalchemy/engine/base.py", line 1771, in _execute_context
    self.dialect.do_execute(
  File "/home/julien/PycharmProjects/website/venv/lib/python3.9/site-packages/sqlalchemy/engine/default.py", line 717, in do_execute
    cursor.execute(statement, parameters)
sqlite3.IntegrityError: UNIQUE constraint failed: user.username

The above exception was the direct cause of the following exception:

Traceback (most recent call last):
  File "/home/julien/PycharmProjects/website/venv/lib/python3.9/site-packages/flask/app.py", line 2070, in wsgi_app
    response = self.full_dispatch_request()
  File "/home/julien/PycharmProjects/website/venv/lib/python3.9/site-packages/flask/app.py", line 1515, in full_dispatch_request
    rv = self.handle_user_exception(e)
  File "/home/julien/PycharmProjects/website/venv/lib/python3.9/site-packages/flask/app.py", line 1513, in full_dispatch_request
    rv = self.dispatch_request()
  File "/home/julien/PycharmProjects/website/venv/lib/python3.9/site-packages/flask/app.py", line 1499, in dispatch_request
    return self.ensure_sync(self.view_functions[rule.endpoint])(**req.view_args)
  File "/home/julien/PycharmProjects/website/venv/lib/python3.9/site-packages/flask_login/utils.py", line 272, in decorated_view
    return func(*args, **kwargs)
  File "/home/julien/PycharmProjects/website/app/blog/routes.py", line 91, in edit_profile
    db.session.commit()
  File "<string>", line 2, in commit
  File "/home/julien/PycharmProjects/website/venv/lib/python3.9/site-packages/sqlalchemy/orm/session.py", line 1428, in commit
    self._transaction.commit(_to_root=self.future)
  File "/home/julien/PycharmProjects/website/venv/lib/python3.9/site-packages/sqlalchemy/orm/session.py", line 829, in commit
    self._prepare_impl()
  File "/home/julien/PycharmProjects/website/venv/lib/python3.9/site-packages/sqlalchemy/orm/session.py", line 808, in _prepare_impl
    self.session.flush()
  File "/home/julien/PycharmProjects/website/venv/lib/python3.9/site-packages/sqlalchemy/orm/session.py", line 3298, in flush
    self._flush(objects)
  File "/home/julien/PycharmProjects/website/venv/lib/python3.9/site-packages/sqlalchemy/orm/session.py", line 3438, in _flush
    transaction.rollback(_capture_exception=True)
  File "/home/julien/PycharmProjects/website/venv/lib/python3.9/site-packages/sqlalchemy/util/langhelpers.py", line 70, in __exit__
    compat.raise_(
  File "/home/julien/PycharmProjects/website/venv/lib/python3.9/site-packages/sqlalchemy/util/compat.py", line 207, in raise_
    raise exception
  File "/home/julien/PycharmProjects/website/venv/lib/python3.9/site-packages/sqlalchemy/orm/session.py", line 3398, in _flush
    flush_context.execute()
  File "/home/julien/PycharmProjects/website/venv/lib/python3.9/site-packages/sqlalchemy/orm/unitofwork.py", line 456, in execute
    rec.execute(self)
  File "/home/julien/PycharmProjects/website/venv/lib/python3.9/site-packages/sqlalchemy/orm/unitofwork.py", line 630, in execute
    util.preloaded.orm_persistence.save_obj(
  File "/home/julien/PycharmProjects/website/venv/lib/python3.9/site-packages/sqlalchemy/orm/persistence.py", line 234, in save_obj
    _emit_update_statements(
  File "/home/julien/PycharmProjects/website/venv/lib/python3.9/site-packages/sqlalchemy/orm/persistence.py", line 998, in _emit_update_statements
    c = connection._execute_20(
  File "/home/julien/PycharmProjects/website/venv/lib/python3.9/site-packages/sqlalchemy/engine/base.py", line 1583, in _execute_20
    return meth(self, args_10style, kwargs_10style, execution_options)
  File "/home/julien/PycharmProjects/website/venv/lib/python3.9/site-packages/sqlalchemy/sql/elements.py", line 323, in _execute_on_connection
    return connection._execute_clauseelement(
  File "/home/julien/PycharmProjects/website/venv/lib/python3.9/site-packages/sqlalchemy/engine/base.py", line 1452, in _execute_clauseelement
    ret = self._execute_context(
  File "/home/julien/PycharmProjects/website/venv/lib/python3.9/site-packages/sqlalchemy/engine/base.py", line 1814, in _execute_context
    self._handle_dbapi_exception(
  File "/home/julien/PycharmProjects/website/venv/lib/python3.9/site-packages/sqlalchemy/engine/base.py", line 1995, in _handle_dbapi_exception
    util.raise_(
  File "/home/julien/PycharmProjects/website/venv/lib/python3.9/site-packages/sqlalchemy/util/compat.py", line 207, in raise_
    raise exception
  File "/home/julien/PycharmProjects/website/venv/lib/python3.9/site-packages/sqlalchemy/engine/base.py", line 1771, in _execute_context
    self.dialect.do_execute(
  File "/home/julien/PycharmProjects/website/venv/lib/python3.9/site-packages/sqlalchemy/engine/default.py", line 717, in do_execute
    cursor.execute(statement, parameters)
sqlalchemy.exc.IntegrityError: (sqlite3.IntegrityError) UNIQUE constraint failed: user.username
[SQL: UPDATE user SET username=?, about_me=? WHERE user.id = ?]
[parameters: ('susan', 'test', 2)]
(Background on this error at: https://sqlalche.me/e/14/gkpj)
[2021-11-13 07:01:15,675] |  ERROR | {/home/julien/PycharmProjects/website/venv/lib/python3.9/site-packages/flask/app.py:1454} | Exception on / [GET]
Traceback (most recent call last):
  File "/home/julien/PycharmProjects/website/venv/lib/python3.9/site-packages/flask/app.py", line 2070, in wsgi_app
    response = self.full_dispatch_request()
  File "/home/julien/PycharmProjects/website/venv/lib/python3.9/site-packages/flask/app.py", line 1515, in full_dispatch_request
    rv = self.handle_user_exception(e)
  File "/home/julien/PycharmProjects/website/venv/lib/python3.9/site-packages/flask/app.py", line 1513, in full_dispatch_request
    rv = self.dispatch_request()
  File "/home/julien/PycharmProjects/website/venv/lib/python3.9/site-packages/flask/app.py", line 1499, in dispatch_request
    return self.ensure_sync(self.view_functions[rule.endpoint])(**req.view_args)
  File "/home/julien/PycharmProjects/website/venv/lib/python3.9/site-packages/flask_login/utils.py", line 272, in decorated_view
    return func(*args, **kwargs)
  File "/home/julien/PycharmProjects/website/app/blog/routes.py", line 27, in index
    return render_template(
  File "/home/julien/PycharmProjects/website/venv/lib/python3.9/site-packages/flask/templating.py", line 147, in render_template
    return _render(
  File "/home/julien/PycharmProjects/website/venv/lib/python3.9/site-packages/flask/templating.py", line 128, in _render
    rv = template.render(context)
  File "/home/julien/PycharmProjects/website/venv/lib/python3.9/site-packages/jinja2/environment.py", line 1291, in render
    self.environment.handle_exception()
  File "/home/julien/PycharmProjects/website/venv/lib/python3.9/site-packages/jinja2/environment.py", line 925, in handle_exception
    raise rewrite_traceback_stack(source=source)
  File "/home/julien/PycharmProjects/website/app/templates/index.html", line 36, in top-level template code
    <li class="next{% if not next_url %} disabled{% endif %}">
  File "/home/julien/PycharmProjects/website/app/templates/base.html", line 1, in top-level template code
    {% extends 'bootstrap/base.html' %}
  File "/home/julien/PycharmProjects/website/venv/lib/python3.9/site-packages/flask_bootstrap/templates/bootstrap/base.html", line 1, in top-level template code
    {% block doc -%}
  File "/home/julien/PycharmProjects/website/venv/lib/python3.9/site-packages/flask_bootstrap/templates/bootstrap/base.html", line 4, in block 'doc'
    {%- block html %}
  File "/home/julien/PycharmProjects/website/venv/lib/python3.9/site-packages/flask_bootstrap/templates/bootstrap/base.html", line 20, in block 'html'
    {% block body -%}
  File "/home/julien/PycharmProjects/website/venv/lib/python3.9/site-packages/flask_bootstrap/templates/bootstrap/base.html", line 21, in block 'body'
    {% block navbar %}
  File "/home/julien/PycharmProjects/website/app/templates/base.html", line 17, in block 'navbar'
    <a class="navbar-brand" href="{{ url_for('main.index') }}">Blog</a>
  File "/home/julien/PycharmProjects/website/venv/lib/python3.9/site-packages/flask/helpers.py", line 338, in url_for
    return appctx.app.handle_url_build_error(error, endpoint, values)
  File "/home/julien/PycharmProjects/website/venv/lib/python3.9/site-packages/flask/helpers.py", line 325, in url_for
    rv = url_adapter.build(
  File "/home/julien/PycharmProjects/website/venv/lib/python3.9/site-packages/werkzeug/routing.py", line 2305, in build
    raise BuildError(endpoint, values, method, self)
werkzeug.routing.BuildError: Could not build url for endpoint 'main.index'. Did you mean 'index' instead?
[2021-11-13 07:02:05,154] |  ERROR | {/home/julien/PycharmProjects/website/venv/lib/python3.9/site-packages/flask/app.py:1454} | Exception on / [GET]
Traceback (most recent call last):
  File "/home/julien/PycharmProjects/website/venv/lib/python3.9/site-packages/flask/app.py", line 2070, in wsgi_app
    response = self.full_dispatch_request()
  File "/home/julien/PycharmProjects/website/venv/lib/python3.9/site-packages/flask/app.py", line 1515, in full_dispatch_request
    rv = self.handle_user_exception(e)
  File "/home/julien/PycharmProjects/website/venv/lib/python3.9/site-packages/flask/app.py", line 1513, in full_dispatch_request
    rv = self.dispatch_request()
  File "/home/julien/PycharmProjects/website/venv/lib/python3.9/site-packages/flask/app.py", line 1499, in dispatch_request
    return self.ensure_sync(self.view_functions[rule.endpoint])(**req.view_args)
  File "/home/julien/PycharmProjects/website/venv/lib/python3.9/site-packages/flask_login/utils.py", line 272, in decorated_view
    return func(*args, **kwargs)
  File "/home/julien/PycharmProjects/website/app/blog/routes.py", line 27, in index
    return render_template(
  File "/home/julien/PycharmProjects/website/venv/lib/python3.9/site-packages/flask/templating.py", line 147, in render_template
    return _render(
  File "/home/julien/PycharmProjects/website/venv/lib/python3.9/site-packages/flask/templating.py", line 128, in _render
    rv = template.render(context)
  File "/home/julien/PycharmProjects/website/venv/lib/python3.9/site-packages/jinja2/environment.py", line 1291, in render
    self.environment.handle_exception()
  File "/home/julien/PycharmProjects/website/venv/lib/python3.9/site-packages/jinja2/environment.py", line 925, in handle_exception
    raise rewrite_traceback_stack(source=source)
  File "/home/julien/PycharmProjects/website/app/templates/index.html", line 36, in top-level template code
    <li class="next{% if not next_url %} disabled{% endif %}">
  File "/home/julien/PycharmProjects/website/app/templates/base.html", line 1, in top-level template code
    {% extends 'bootstrap/base.html' %}
  File "/home/julien/PycharmProjects/website/venv/lib/python3.9/site-packages/flask_bootstrap/templates/bootstrap/base.html", line 1, in top-level template code
    {% block doc -%}
  File "/home/julien/PycharmProjects/website/venv/lib/python3.9/site-packages/flask_bootstrap/templates/bootstrap/base.html", line 4, in block 'doc'
    {%- block html %}
  File "/home/julien/PycharmProjects/website/venv/lib/python3.9/site-packages/flask_bootstrap/templates/bootstrap/base.html", line 20, in block 'html'
    {% block body -%}
  File "/home/julien/PycharmProjects/website/venv/lib/python3.9/site-packages/flask_bootstrap/templates/bootstrap/base.html", line 21, in block 'body'
    {% block navbar %}
  File "/home/julien/PycharmProjects/website/app/templates/base.html", line 17, in block 'navbar'
    <a class="navbar-brand" href="{{ url_for('main.index') }}">Blog</a>
  File "/home/julien/PycharmProjects/website/venv/lib/python3.9/site-packages/flask/helpers.py", line 338, in url_for
    return appctx.app.handle_url_build_error(error, endpoint, values)
  File "/home/julien/PycharmProjects/website/venv/lib/python3.9/site-packages/flask/helpers.py", line 325, in url_for
    rv = url_adapter.build(
  File "/home/julien/PycharmProjects/website/venv/lib/python3.9/site-packages/werkzeug/routing.py", line 2305, in build
    raise BuildError(endpoint, values, method, self)
werkzeug.routing.BuildError: Could not build url for endpoint 'main.index'. Did you mean 'index' instead?
